<mujoco model="g1_29dof_with_hand_rev_1_0">
<!-- g1 29 + 2f85_v4  -->
  <compiler angle="radian" meshdir="meshes"/>
<!-- <option timestep='0.001' iterations='50' solver='PGS' gravity='0 0 -9.81'>
    </option>
    <size njmax="500" nconmax="100" /> -->
    
  <default>
    <joint damping="0.001" armature="0.01" frictionloss="0.1"/>
  </default>


  <asset>
    <material name="metal" rgba="0.58 0.58 0.58 1"/>
    <material name="silicone" rgba="0.1882 0.1882 0.1882 1"/>
    <material name="black" rgba="0.149 0.149 0.149 1"/>

    <mesh file="2f85_v4/base.stl"/>
    <mesh file="2f85_v4/base_coupling.stl"/>
    <mesh file="2f85_v4/c-a01-85-open.stl"/>
    <mesh file="2f85_v4/driver.stl"/>
    <mesh file="2f85_v4/coupler.stl"/>
    <mesh file="2f85_v4/spring_link.stl"/>
    <mesh file="2f85_v4/follower.stl"/>
    <mesh file="2f85_v4/tongue.stl"/>

    <mesh name="pelvis" file="pelvis.STL"/>
    <mesh name="pelvis_contour_link" file="pelvis_contour_link.STL"/>
    <mesh name="left_hip_pitch_link" file="left_hip_pitch_link.STL"/>
    <mesh name="left_hip_roll_link" file="left_hip_roll_link.STL"/>
    <mesh name="left_hip_yaw_link" file="left_hip_yaw_link.STL"/>
    <mesh name="left_knee_link" file="left_knee_link.STL"/>
    <mesh name="left_ankle_pitch_link" file="left_ankle_pitch_link.STL"/>
    <mesh name="left_ankle_roll_link" file="left_ankle_roll_link.STL"/>
    <mesh name="right_hip_pitch_link" file="right_hip_pitch_link.STL"/>
    <mesh name="right_hip_roll_link" file="right_hip_roll_link.STL"/>
    <mesh name="right_hip_yaw_link" file="right_hip_yaw_link.STL"/>
    <mesh name="right_knee_link" file="right_knee_link.STL"/>
    <mesh name="right_ankle_pitch_link" file="right_ankle_pitch_link.STL"/>
    <mesh name="right_ankle_roll_link" file="right_ankle_roll_link.STL"/>
    <mesh name="waist_yaw_link_rev_1_0" file="waist_yaw_link_rev_1_0.STL"/>
    <mesh name="waist_roll_link_rev_1_0" file="waist_roll_link_rev_1_0.STL"/>
    <mesh name="torso_link_rev_1_0" file="torso_link_rev_1_0.STL"/>
    <mesh name="logo_link" file="logo_link.STL"/>
    <mesh name="head_link" file="head_link.STL"/>
    <mesh name="left_shoulder_pitch_link" file="left_shoulder_pitch_link.STL"/>
    <mesh name="left_shoulder_roll_link" file="left_shoulder_roll_link.STL"/>
    <mesh name="left_shoulder_yaw_link" file="left_shoulder_yaw_link.STL"/>
    <mesh name="left_elbow_link" file="left_elbow_link.STL"/>
    <mesh name="left_wrist_roll_link" file="left_wrist_roll_link.STL"/>
    <mesh name="left_wrist_pitch_link" file="left_wrist_pitch_link.STL"/>
    <mesh name="left_wrist_yaw_link" file="left_wrist_yaw_link.STL"/>
    <mesh name="right_shoulder_pitch_link" file="right_shoulder_pitch_link.STL"/>
    <mesh name="right_shoulder_roll_link" file="right_shoulder_roll_link.STL"/>
    <mesh name="right_shoulder_yaw_link" file="right_shoulder_yaw_link.STL"/>
    <mesh name="right_elbow_link" file="right_elbow_link.STL"/>
    <mesh name="right_wrist_roll_link" file="right_wrist_roll_link.STL"/>
    <mesh name="right_wrist_pitch_link" file="right_wrist_pitch_link.STL"/>
    <mesh name="right_wrist_yaw_link" file="right_wrist_yaw_link.STL"/>
  </asset>

<default>
    <default class="2f85">
      <mesh scale="0.001 0.001 0.001"/>
      <general biastype="affine"/>

      <joint axis="0 0 1"/>
      <default class="driver">
        <joint range="0 0.9" armature="0.005" damping="0.1" solimplimit="0.95 0.99 0.001" solreflimit="0.005 1"/>
      </default>
      <default class="follower">
        <joint range="-0.872664 0.9" armature="0.001"  solimplimit="0.95 0.99 0.001" solreflimit="0.005 1"/>
      </default>
      <default class="spring_link">
        <joint range="-0.29670597283 0.9" armature="0.001" stiffness="0.05" springref="2.62" damping="0.00125"/>
      </default>
      <default class="coupler">
        <joint range="-1.57 0" armature="0.001" solimplimit="0.95 0.99 0.001" solreflimit="0.005 1"/>
      </default>

      <default class="visual">
        <geom type="mesh" contype="0" conaffinity="0" group="2" material="black"/>
      </default>
      <default class="collision">
        <geom type="mesh" group="3"/>
        <default class="pad_box1">
          <geom mass="1e-6" type="box" pos="0.043258  0 0.12"  size="0.002 0.011 0.009375" friction="0.9"
            solimp="0.95 0.99 0.001" solref="0.004 1" priority="1" rgba="0.55 0.55 0.55 1"/>
        </default>
        <default class="pad_box2">
          <geom mass="1e-6" type="box" pos="0.043258 0 0.13875" size="0.002 0.011 0.009375" friction="0.9"
            solimp="0.95 0.99 0.001" solref="0.004 1" priority="1" rgba="0.45 0.45 0.45 1"/>
        </default>
      </default>
    </default>
  </default>

  <worldbody>

    <body name="pelvis" pos="0 0 0.793">
      <inertial pos="0 0 -0.0760301" quat="1 0 -0.000398273 0" mass="3.814" diaginertia="0.0105549 0.00931478 0.0079185"/>
      <joint name="floating_base_joint" type="free" limited="false" actuatorfrclimited="false"/>
      <geom type="mesh" contype="0" conaffinity="0" group="1" density="0" rgba="0.2 0.2 0.2 1" mesh="pelvis"/>
      <geom type="mesh" contype="0" conaffinity="0" group="1" density="0" rgba="0.7 0.7 0.7 1" mesh="pelvis_contour_link"/>
      <geom type="mesh" rgba="0.7 0.7 0.7 1" mesh="pelvis_contour_link"/>
      <site name="imu_in_pelvis" size="0.01" pos="0.04525 0 -0.08339"/>
      <body name="left_hip_pitch_link" pos="0 0.064452 -0.1027">
        <inertial pos="0.002741 0.047791 -0.02606" quat="0.954862 0.293964 0.0302556 0.030122" mass="1.35" diaginertia="0.00181517 0.00153422 0.00116212"/>
        <joint name="left_hip_pitch_joint" pos="0 0 0" axis="0 1 0" range="-2.5307 2.8798" actuatorfrcrange="-88 88"/>
        <geom type="mesh" contype="0" conaffinity="0" group="1" density="0" rgba="0.2 0.2 0.2 1" mesh="left_hip_pitch_link"/>
        <!-- <geom type="mesh" rgba="0.2 0.2 0.2 1" mesh="left_hip_pitch_link"/> -->
        <body name="left_hip_roll_link" pos="0 0.052 -0.030465" quat="0.996179 0 -0.0873386 0">
          <inertial pos="0.029812 -0.001045 -0.087934" quat="0.977808 -1.97119e-05 0.205576 -0.0403793" mass="1.52" diaginertia="0.00254986 0.00241169 0.00148755"/>
          <joint name="left_hip_roll_joint" pos="0 0 0" axis="1 0 0" range="-0.5236 2.9671" actuatorfrcrange="-139 139"/>
          <geom type="mesh" contype="0" conaffinity="0" group="1" density="0" rgba="0.7 0.7 0.7 1" mesh="left_hip_roll_link"/>
          <!-- <geom type="mesh" rgba="0.7 0.7 0.7 1" mesh="left_hip_roll_link" name="left_hip_roll_stl"/> -->
          <body name="left_hip_yaw_link" pos="0.025001 0 -0.12412">
            <inertial pos="-0.057709 -0.010981 -0.15078" quat="0.600598 0.15832 0.223482 0.751181" mass="1.702" diaginertia="0.00776166 0.00717575 0.00160139"/>
            <joint name="left_hip_yaw_joint" pos="0 0 0" axis="0 0 1" range="-2.7576 2.7576" actuatorfrcrange="-88 88"/>
            <geom type="mesh" contype="0" conaffinity="0" group="1" density="0" rgba="0.7 0.7 0.7 1" mesh="left_hip_yaw_link"/>
            <!-- <geom type="mesh" rgba="0.7 0.7 0.7 1" mesh="left_hip_yaw_link"/> -->
            <body name="left_knee_link" pos="-0.078273 0.0021489 -0.17734" quat="0.996179 0 0.0873386 0">
              <inertial pos="0.005457 0.003964 -0.12074" quat="0.923418 -0.0327699 0.0158246 0.382067" mass="1.932" diaginertia="0.0113804 0.0112778 0.00146458"/>
              <joint name="left_knee_joint" pos="0 0 0" axis="0 1 0" range="-0.087267 2.8798" actuatorfrcrange="-139 139"/>
              <geom type="mesh" contype="0" conaffinity="0" group="1" density="0" rgba="0.7 0.7 0.7 1" mesh="left_knee_link"/>
              <!-- <geom type="mesh" rgba="0.7 0.7 0.7 1" mesh="left_knee_link"/> -->
              <body name="left_ankle_pitch_link" pos="0 -9.4445e-05 -0.30001">
                <inertial pos="-0.007269 0 0.011137" quat="0.603053 0.369225 0.369225 0.603053" mass="0.074" diaginertia="1.89e-05 1.40805e-05 6.9195e-06"/>
                <joint name="left_ankle_pitch_joint" pos="0 0 0" axis="0 1 0" range="-0.87267 0.5236" actuatorfrcrange="-50 50"/>
                <geom type="mesh" contype="0" conaffinity="0" group="1" density="0" rgba="0.7 0.7 0.7 1" mesh="left_ankle_pitch_link"/>
                <!-- <geom type="mesh" rgba="0.7 0.7 0.7 1" mesh="left_ankle_pitch_link"/> -->
                <body name="left_ankle_roll_link" pos="0 0 -0.017558">
                  <inertial pos="0.026505 0 -0.016425" quat="-0.000481092 0.728482 -0.000618967 0.685065" mass="0.608" diaginertia="0.00167218 0.0016161 0.000217621"/>
                  <joint name="left_ankle_roll_joint" pos="0 0 0" axis="1 0 0" range="-0.2618 0.2618" actuatorfrcrange="-50 50"/>
                  <geom type="mesh" contype="0" conaffinity="0" group="1" density="0" rgba="0.2 0.2 0.2 1" mesh="left_ankle_roll_link"/>
                  <geom size="0.005" pos="-0.05 0.025 -0.03" rgba="0.2 0.2 0.2 1"/>
                  <geom size="0.005" pos="-0.05 -0.025 -0.03" rgba="0.2 0.2 0.2 1"/>
                  <geom size="0.005" pos="0.12 0.03 -0.03" rgba="0.2 0.2 0.2 1"/>
                  <geom size="0.005" pos="0.12 -0.03 -0.03" rgba="0.2 0.2 0.2 1"/>
                </body>
              </body>
            </body>
          </body>
        </body>
      </body>
      <body name="right_hip_pitch_link" pos="0 -0.064452 -0.1027">
        <inertial pos="0.002741 -0.047791 -0.02606" quat="0.954862 -0.293964 0.0302556 -0.030122" mass="1.35" diaginertia="0.00181517 0.00153422 0.00116212"/>
        <joint name="right_hip_pitch_joint" pos="0 0 0" axis="0 1 0" range="-2.5307 2.8798" actuatorfrcrange="-88 88"/>
        <geom type="mesh" contype="0" conaffinity="0" group="1" density="0" rgba="0.2 0.2 0.2 1" mesh="right_hip_pitch_link"/>
        <!-- <geom type="mesh" rgba="0.2 0.2 0.2 1" mesh="right_hip_pitch_link"/> -->
        <body name="right_hip_roll_link" pos="0 -0.052 -0.030465" quat="0.996179 0 -0.0873386 0">
          <inertial pos="0.029812 0.001045 -0.087934" quat="0.977808 1.97119e-05 0.205576 0.0403793" mass="1.52" diaginertia="0.00254986 0.00241169 0.00148755"/>
          <joint name="right_hip_roll_joint" pos="0 0 0" axis="1 0 0" range="-2.9671 0.5236" actuatorfrcrange="-139 139"/>
          <geom type="mesh" contype="0" conaffinity="0" group="1" density="0" rgba="0.7 0.7 0.7 1" mesh="right_hip_roll_link"/>
          <!-- <geom type="mesh" rgba="0.7 0.7 0.7 1" mesh="right_hip_roll_link" name="right_hip_roll_stl"/> -->
          <body name="right_hip_yaw_link" pos="0.025001 0 -0.12412">
            <inertial pos="-0.057709 0.010981 -0.15078" quat="0.751181 0.223482 0.15832 0.600598" mass="1.702" diaginertia="0.00776166 0.00717575 0.00160139"/>
            <joint name="right_hip_yaw_joint" pos="0 0 0" axis="0 0 1" range="-2.7576 2.7576" actuatorfrcrange="-88 88"/>
            <geom type="mesh" contype="0" conaffinity="0" group="1" density="0" rgba="0.7 0.7 0.7 1" mesh="right_hip_yaw_link"/>
            <!-- <geom type="mesh" rgba="0.7 0.7 0.7 1" mesh="right_hip_yaw_link"/> -->
            <body name="right_knee_link" pos="-0.078273 -0.0021489 -0.17734" quat="0.996179 0 0.0873386 0">
              <inertial pos="0.005457 -0.003964 -0.12074" quat="0.923439 0.0345276 0.0116333 -0.382012" mass="1.932" diaginertia="0.011374 0.0112843 0.00146452"/>
              <joint name="right_knee_joint" pos="0 0 0" axis="0 1 0" range="-0.087267 2.8798" actuatorfrcrange="-139 139"/>
              <geom type="mesh" contype="0" conaffinity="0" group="1" density="0" rgba="0.7 0.7 0.7 1" mesh="right_knee_link"/>
              <!-- <geom type="mesh" rgba="0.7 0.7 0.7 1" mesh="right_knee_link"/> -->
              <body name="right_ankle_pitch_link" pos="0 9.4445e-05 -0.30001">
                <inertial pos="-0.007269 0 0.011137" quat="0.603053 0.369225 0.369225 0.603053" mass="0.074" diaginertia="1.89e-05 1.40805e-05 6.9195e-06"/>
                <joint name="right_ankle_pitch_joint" pos="0 0 0" axis="0 1 0" range="-0.87267 0.5236" actuatorfrcrange="-50 50"/>
                <geom type="mesh" contype="0" conaffinity="0" group="1" density="0" rgba="0.7 0.7 0.7 1" mesh="right_ankle_pitch_link"/>
                <!-- <geom type="mesh" rgba="0.7 0.7 0.7 1" mesh="right_ankle_pitch_link"/> -->
                <body name="right_ankle_roll_link" pos="0 0 -0.017558">
                  <inertial pos="0.026505 0 -0.016425" quat="0.000481092 0.728482 0.000618967 0.685065" mass="0.608" diaginertia="0.00167218 0.0016161 0.000217621"/>
                  <joint name="right_ankle_roll_joint" pos="0 0 0" axis="1 0 0" range="-0.2618 0.2618" actuatorfrcrange="-50 50"/>
                  <geom type="mesh" contype="0" conaffinity="0" group="1" density="0" rgba="0.2 0.2 0.2 1" mesh="right_ankle_roll_link"/>
                  <geom size="0.005" pos="-0.05 0.025 -0.03" rgba="0.2 0.2 0.2 1"/>
                  <geom size="0.005" pos="-0.05 -0.025 -0.03" rgba="0.2 0.2 0.2 1"/>
                  <geom size="0.005" pos="0.12 0.03 -0.03" rgba="0.2 0.2 0.2 1"/>
                  <geom size="0.005" pos="0.12 -0.03 -0.03" rgba="0.2 0.2 0.2 1"/>
                </body>
              </body>
            </body>
          </body>
        </body>
      </body>
      <body name="waist_yaw_link">
        <inertial pos="0.003494 0.000233 0.018034" quat="0.289697 0.591001 -0.337795 0.672821" mass="0.214" diaginertia="0.000163531 0.000107714 0.000102205"/>
        <joint name="waist_yaw_joint" pos="0 0 0" axis="0 0 1" range="-2.618 2.618" actuatorfrcrange="-88 88"/>
        <geom type="mesh" contype="0" conaffinity="0" group="1" density="0" rgba="0.7 0.7 0.7 1" mesh="waist_yaw_link_rev_1_0"/>
        <body name="waist_roll_link" pos="-0.0039635 0 0.044">
          <inertial pos="0 2.3e-05 0" quat="0.5 0.5 -0.5 0.5" mass="0.086" diaginertia="8.245e-06 7.079e-06 6.339e-06"/>
          <!-- <joint name="waist_roll_joint" pos="0 0 0" axis="1 0 0" range="-0.52 0.52" actuatorfrcrange="-50 50"/> -->
          <geom type="mesh" contype="0" conaffinity="0" group="1" density="0" rgba="0.7 0.7 0.7 1" mesh="waist_roll_link_rev_1_0"/>
          <body name="torso_link">
            <inertial pos="0.00203133 0.000339727 0.184597" quat="0.999802 -5.98967e-05 0.0198391 0.0013197" mass="7.817" diaginertia="0.121795 0.109773 0.0273733"/>
            <!-- <joint name="waist_pitch_joint" pos="0 0 0" axis="0 1 0" range="-0.52 0.52" actuatorfrcrange="-50 50"/> -->
            <geom type="mesh" contype="0" conaffinity="0" group="1" density="0" rgba="0.7 0.7 0.7 1" mesh="torso_link_rev_1_0"/>
            <geom type="mesh" rgba="0.7 0.7 0.7 1" mesh="torso_link_rev_1_0" name="torso_stl"/>
            <geom pos="0.0039635 0 -0.044" quat="1 0 0 0" type="mesh" contype="0" conaffinity="0" group="1" density="0" rgba="0.2 0.2 0.2 1" mesh="logo_link"/>
            <!-- <geom pos="0.0039635 0 -0.044" quat="1 0 0 0" type="mesh" rgba="0.2 0.2 0.2 1" mesh="logo_link"/> -->
            <geom pos="0.0039635 0 -0.044" type="mesh" contype="0" conaffinity="0" group="1" density="0" rgba="0.2 0.2 0.2 1" mesh="head_link"/>
            <!-- <geom pos="0.0039635 0 -0.044" type="mesh" rgba="0.2 0.2 0.2 1" mesh="head_link"/> -->

            <site name="imu_in_torso" size="0.01" pos="-0.03959 -0.00224 0.14792"/>
            <body name="imu_in_torso" pos="-0.03959 -0.00224 0.14792"></body>
            <body name="left_shoulder_pitch_link" pos="0.0039563 0.10022 0.24778" quat="0.990264 0.139201 1.38722e-05 -9.86868e-05">
              <inertial pos="0 0.035892 -0.011628" quat="0.654152 0.0130458 -0.326267 0.68225" mass="0.718" diaginertia="0.000465864 0.000432842 0.000406394"/>
              <joint name="left_shoulder_pitch_joint" pos="0 0 0" axis="0 1 0" range="-3.0892 2.6704" actuatorfrcrange="-25 25"/>
              <geom type="mesh" contype="0" conaffinity="0" group="1" density="0" rgba="0.7 0.7 0.7 1" mesh="left_shoulder_pitch_link"/>
              <geom type="mesh" rgba="0.7 0.7 0.7 1" mesh="left_shoulder_pitch_link"/>
              <!-- <geom size="0.03 0.025" pos="0 0.04 -0.01" quat="0.707107 0 0.707107 0" type="cylinder" rgba="0.7 0.7 0.7 1" name="left_shoulder_pitch_stl"/> -->
              <body name="left_shoulder_roll_link" pos="0 0.038 -0.013831" quat="0.990268 -0.139172 0 0">
                <inertial pos="-0.000227 0.00727 -0.063243" quat="0.701256 -0.0196223 -0.00710317 0.712604" mass="0.643" diaginertia="0.000691311 0.000618011 0.000388977"/>
                <joint name="left_shoulder_roll_joint" pos="0 0 0" axis="1 0 0" range="-1.5882 2.2515" actuatorfrcrange="-25 25"/>
                <geom type="mesh" contype="0" conaffinity="0" group="1" density="0" rgba="0.7 0.7 0.7 1" mesh="left_shoulder_roll_link"/>
                <geom type="mesh" rgba="0.7 0.7 0.7 1" mesh="left_shoulder_roll_link"/>
                <!-- <geom size="0.03 0.015" pos="-0.004 0.006 -0.053" type="cylinder" rgba="0.7 0.7 0.7 1" name="left_shoulder_roll_stl" /> -->
                <body name="left_shoulder_yaw_link" pos="0 0.00624 -0.1032">
                  <inertial pos="0.010773 -0.002949 -0.072009" quat="0.716879 -0.0964829 -0.0679942 0.687134" mass="0.734" diaginertia="0.00106187 0.00103217 0.000400661"/>
                  <joint name="left_shoulder_yaw_joint" pos="0 0 0" axis="0 0 1" range="-2.618 2.618" actuatorfrcrange="-25 25"/>
                  <geom type="mesh" contype="0" conaffinity="0" group="1" density="0" rgba="0.7 0.7 0.7 1" mesh="left_shoulder_yaw_link"/>
                  <geom type="mesh" rgba="0.7 0.7 0.7 1" mesh="left_shoulder_yaw_link" name="left_shoulder_yaw_stl"/>
                  <body name="left_elbow_link" pos="0.015783 0 -0.080518">
                    <inertial pos="0.064956 0.004454 -0.010062" quat="0.541765 0.636132 0.388821 0.388129" mass="0.6" diaginertia="0.000443035 0.000421612 0.000259353"/>
                    <joint name="left_elbow_joint" pos="0 0 0" axis="0 1 0" range="-1.0472 2.0944" actuatorfrcrange="-25 25"/>
                    <geom type="mesh" contype="0" conaffinity="0" group="1" density="0" rgba="0.7 0.7 0.7 1" mesh="left_elbow_link"/>
                    <geom type="mesh" rgba="0.7 0.7 0.7 1" mesh="left_elbow_link" name="left_elbow_stl"/>
                    <body name="left_wrist_roll_link" pos="0.1 0.00188791 -0.01">
                      <inertial pos="0.0171394 0.000537591 4.8864e-07" quat="0.575338 0.411667 -0.574906 0.411094" mass="0.085445" diaginertia="5.48211e-05 4.96646e-05 3.57798e-05"/>
                      <joint name="left_wrist_roll_joint" pos="0 0 0" axis="1 0 0" range="-1.97222 1.97222" actuatorfrcrange="-25 25"/>
                      <geom type="mesh" contype="0" conaffinity="0" group="1" density="0" rgba="0.7 0.7 0.7 1" mesh="left_wrist_roll_link"/>
                      <geom type="mesh" rgba="0.7 0.7 0.7 1" mesh="left_wrist_roll_link" name="left_wrist_roll_stl"/>

                      <body name="left_wrist_pitch_link" pos="0.038 0 0">
                        <inertial pos="0.0229999 -0.00111685 -0.00111658" quat="0.249998 0.661363 0.293036 0.643608" mass="0.48405" diaginertia="0.000430353 0.000429873 0.000164648"/>
                        <joint name="left_wrist_pitch_joint" pos="0 0 0" axis="0 1 0" range="-1.61443 1.61443" actuatorfrcrange="-25 25"/>
                        <geom type="mesh" contype="0" conaffinity="0" group="1" density="0" rgba="0.7 0.7 0.7 1" mesh="left_wrist_pitch_link"/>
                        <geom type="mesh" rgba="0.7 0.7 0.7 1" mesh="left_wrist_pitch_link" name="left_wrist_pitch_stl" />
                        <body name="left_wrist_yaw_link" pos="0.046 0 0">
                          <inertial pos="0.0609957 0.00246187 -5.70275e-05" quat="0.481367 0.502961 0.514824 0.500273" mass="0.393726" diaginertia="0.000531179 0.0004935 0.000248299"/>
                          <joint name="left_wrist_yaw_joint" pos="0 0 0" axis="0 0 1" range="-1.61443 1.61443" actuatorfrcrange="-25 25"/>
                          <geom type="mesh" contype="0" conaffinity="0" group="1" density="0" rgba="0.7 0.7 0.7 1" mesh="left_wrist_yaw_link"/>
                          <geom type="mesh" rgba="0.7 0.7 0.7 1" mesh="left_wrist_yaw_link" name="left_wrist_yaw_stl"/>
                          
                          <!-- left 2f85_v4 -->
                          <body name="left_arm_base" childclass="2f85" pos="0.0415 0.003 0" quat="0.5 0.5 0.5 0.5">
                            <inertial mass="0.777441" pos="0 -2.70394e-05 0.0354675" quat="1 0 0 0"
                              diaginertia="0.000260285 0.000225381 0.000152708"/>
                            <geom class="visual" pos="0 0 0.0108" quat="0 0 0 1"   mesh="base"/>
                            <geom class="visual" pos="0 0 0.004" quat="1 -1 0 0"   mesh="base_coupling"/>
                            <geom class="visual" pos="0 0 0.0108" quat="1 0 0 0"  material="metal" mesh="c-a01-85-open"/>
                            <geom name="left_arm_hand_capsule" class="collision" type="capsule" conaffinity="1" size="0.04 0.06" rgba="1 1 1 0.3" pos="0 0 0.01"/>
                              <!-- pos 1 y  2 z 3 x-->
                            <!-- left finger site -->
                            <site name="Left_gripper_center" pos="0 0 0.16" size="0.01" type="sphere" rgba="1 0 0 1"/>
    
                            <!-- Left-hand side 4-bar linkage -->
                            <body name="left_arm_left_driver" pos="-0.0306011 0.00475 0.0657045" quat="1 -1 0 0">
                              <inertial mass="0.00899563" pos="0 0.0177547 0.00107314" quat="0.681301 0.732003 0 0"
                                  diaginertia="1.72352e-06 1.60906e-06 3.22006e-07"/>
                              <joint name="left_arm_left_driver_joint" class="driver"/>
                              <geom class="visual" pos="0.0306011 0.0549045 -0.0047" quat="1 1 0 0"  material="metal" mesh="driver"/>
                              <body name="left_arm_left_coupler" pos="-0.0314249 0.00453223 -0.0102" quat="0 0 0 1">
                                <inertial mass="0.0140974" pos="0 0.00301209 0.0232175" quat="0.705636 -0.0455904 0.0455904 0.705636"
                                diaginertia="4.16206e-06 3.52216e-06 8.88131e-07"/>
                                <geom class="visual" pos="-0.062026 -0.0503723 0.0055" quat="1 -1 0 0"   mesh="coupler"/>
                                <geom name="left_arm_left_coupler_col_1" class="pad_box2" pos="0.005 0.025 0.01" quat="1 1 -0.1 0" type="capsule" size="0.009 0.02"/>
                                <geom name="left_arm_left_coupler_col_2" class="pad_box2" pos="0.005 0.025 0.001" quat="1 1 -0.1 0" type="capsule" size="0.009 0.02"/>
                              </body>
                            </body>
                            <body name="left_arm_left_spring_link" pos="-0.0127 -0.012 0.07222" quat="1 -1 0 0">
                              <inertial mass="0.0221642" pos="-8.65005e-09 0.0181624 0.0212658" quat="0.663403 -0.244737 0.244737 0.663403"
                                  diaginertia="8.96853e-06 6.71733e-06 2.63931e-06"/>
                              <joint name="left_arm_left_spring_link_joint" class="spring_link"/>
                              <geom class="visual" pos="0.0127 0.06142 0.01205" quat="1 1 0 0" type="mesh"  mesh="spring_link"/>
                              <body name="left_arm_left_follower" pos="-0.0382079 -0.0425003 0.00295" quat="0 -1 0 0">
                                <inertial mass="0.0125222" pos="0 -0.011046 0.0124786" quat="1 0.1664 0 0"
                                diaginertia="2.67415e-06 2.4559e-06 6.02031e-07"/>
                                <joint name="left_arm_left_follower" class="follower"/>
                                <geom class="visual" pos="0.0509079 -0.10392 -0.0091" quat="1 -1 0 0" type="mesh"  mesh="follower"/>
                                <geom class="visual" pos="0.0509079 -0.10392 -0.0091" quat="1 -1 0 0" type="mesh" material="metal" mesh="tongue"/>
                                <geom name="left_arm_left_follower_pad2" class="pad_box2" type="capsule" size="0.009 0.012 0.008" pos="-0.0035 -0.002 -0.009" quat="1 1 0 0"/>
                                  <site name="left_arm_left_follower_site"  type="box" size="0.03 0.045 0.015" pos="0 -0.03 -0.01" 
                                        rgba="1 0 0 0.0"/>
                                <body name="left_arm_left_pad" pos="-0.0377897 -0.103916 -0.0091" quat="1 -1 0 0">
                                  <geom class="pad_box2" name="left_arm_left_finger_pad"/>
                                  <site name="left_arm_left_pad_site"  type="box" size="0.006 0.015 0.02" pos="0.042 0 0.13" 
                                      rgba="1 0 0 0.0"/>
                                </body>
                              </body>
                            </body>
                            <!-- Right-hand side 4-bar linkage -->
                            <body name="left_arm_right_driver" pos="0.0306011 -0.00475 0.0657045" quat="0 0 -1 1">
                              <inertial mass="0.00899563" pos="2.96931e-12 0.0177547 0.00107314" quat="0.681301 0.732003 0 0"
                              diaginertia="1.72352e-06 1.60906e-06 3.22006e-07"/>
                              <joint name="left_arm_right_driver_joint" class="driver"/>
                              <geom class="visual" pos="0.0306011 0.0549045 -0.0047" quat="1 1 0 0" material="metal" mesh="driver"/>
                              <body name="left_arm_right_coupler" pos="-0.0314249 0.00453223 -0.0102" quat="0 0 0 1">
                                <inertial mass="0.0140974" pos="0 0.00301209 0.0232175" quat="0.705636 -0.0455904 0.0455904 0.705636"
                                diaginertia="4.16206e-06 3.52216e-06 8.88131e-07"/>
                                <geom class="visual" pos="-0.062026 -0.0503723 0.0055" quat="1 -1 0 0"   mesh="coupler"/>
                                <geom name="left_arm_right_coupler_col_1" class="pad_box2" pos="0.005 0.025 0.01" quat="1 1 -0.1 0" type="capsule" size="0.009 0.02"/>
                                <geom name="left_arm_right_coupler_col_2" class="pad_box2" pos="0.005 0.025 0.001" quat="1 1 -0.1 0" type="capsule" size="0.009 0.02"/>
                              </body>
                            </body>
                            <body name="left_arm_right_spring_link" pos="0.0127 0.012 0.07222" quat="0 0 -1 1">
                              <inertial mass="0.0221642" pos="-8.65005e-09 0.0181624 0.0212658" quat="0.663403 -0.244737 0.244737 0.663403"
                              diaginertia="8.96853e-06 6.71733e-06 2.63931e-06"/>
                              <joint name="left_arm_right_spring_link_joint" class="spring_link"/>
                              <geom class="visual" pos="0.0127 0.06142 0.01205" quat="1 1 0 0"   mesh="spring_link"/>
                              <body name="left_arm_right_follower" pos="-0.0382079 -0.0425003 0.00295" quat="0 -1 0 0">
                                <inertial mass="0.0125222" pos="0 -0.011046 0.0124786" quat="1 0.1664 0 0"
                                diaginertia="2.67415e-06 2.4559e-06 6.02031e-07"/>
                                <joint name="left_arm_right_follower_joint" class="follower"/>
                                <geom class="visual" pos="0.0509079 -0.10392 -0.0091" quat="1 -1 0 0" material="metal" mesh="tongue"/>
                                <geom class="visual" pos="0.0509079 -0.10392 -0.0091" quat="1 -1 0 0" mesh="follower"/>
                                <geom name="left_arm_right_follower_pad2" class="pad_box2" type="capsule" size="0.009 0.012 0.008" pos="-0.0035 -0.002 -0.009" quat="1 1 0 0"/>
                                <site name="left_arm_right_follower_site"  type="box" size="0.03 0.045 0.015" pos="0 -0.03 -0.01" 
                                        rgba="1 0 0 0.0"/>
                                <body name="left_arm_right_pad" pos="-0.0377897 -0.103916 -0.0091" quat="1 -1 0 0">
                                  <geom class="pad_box2" name="left_arm_right_finger_pad"/>
                                  <site name="left_arm_right_pad_site" type="box" size="0.006 0.015 0.02" pos="0.042 0 0.13" 
                                              rgba="1 0 0 0.0"/>
                                </body>
                              </body>
                            </body>
                          </body>
                          <!-- end left 2f85_v4 -->
                         
                        </body>
                      </body>
                    </body>
                  </body>
                </body>
              </body>
            </body>
            <body name="right_shoulder_pitch_link" pos="0.0039563 -0.10021 0.24778" quat="0.990264 -0.139201 1.38722e-05 9.86868e-05">
              <inertial pos="0 -0.035892 -0.011628" quat="0.68225 -0.326267 0.0130458 0.654152" mass="0.718" diaginertia="0.000465864 0.000432842 0.000406394"/>
              <joint name="right_shoulder_pitch_joint" pos="0 0 0" axis="0 1 0" range="-3.0892 2.6704" actuatorfrcrange="-25 25"/>
              <geom type="mesh" contype="0" conaffinity="0" group="1" density="0" rgba="0.7 0.7 0.7 1" mesh="right_shoulder_pitch_link"/>
              <geom type="mesh" rgba="0.7 0.7 0.7 1" mesh="right_shoulder_pitch_link"/>
              <geom size="0.03 0.025" pos="0 -0.04 -0.01" quat="0.707107 0 0.707107 0" type="cylinder" rgba="0.7 0.7 0.7 1"/>
              <body name="right_shoulder_roll_link" pos="0 -0.038 -0.013831" quat="0.990268 0.139172 0 0">
                <inertial pos="-0.000227 -0.00727 -0.063243" quat="0.712604 -0.00710317 -0.0196223 0.701256" mass="0.643" diaginertia="0.000691311 0.000618011 0.000388977"/>
                <joint name="right_shoulder_roll_joint" pos="0 0 0" axis="1 0 0" range="-2.2515 1.5882" actuatorfrcrange="-25 25"
                   />
                <!-- <geom type="mesh" contype="0" conaffinity="0" group="1" density="0" rgba="0.7 0.7 0.7 1" mesh="right_shoulder_roll_link"/> -->
                <geom type="mesh" rgba="0.7 0.7 0.7 1" mesh="right_shoulder_roll_link"/>
                <!-- <geom size="0.03 0.015" pos="-0.004 -0.006 -0.053" type="cylinder" rgba="0.7 0.7 0.7 1" /> -->
               
                <body name="right_shoulder_yaw_link" pos="0 -0.00624 -0.1032">
                  <inertial pos="0.010773 0.002949 -0.072009" quat="0.687134 -0.0679942 -0.0964829 0.716879" mass="0.734" diaginertia="0.00106187 0.00103217 0.000400661"/>
                  <joint name="right_shoulder_yaw_joint" pos="0 0 0" axis="0 0 1" range="-2.618 2.618" actuatorfrcrange="-25 25"/>
                  <!-- <geom type="mesh" contype="0" conaffinity="0" group="1" density="0" rgba="0.7 0.7 0.7 1" mesh="right_shoulder_yaw_link"/> -->
                  <geom type="mesh" rgba="0.7 0.7 0.7 1" mesh="right_shoulder_yaw_link" name="right_shoulder_yaw_stl"/>

                  <body name="right_elbow_link" pos="0.015783 0 -0.080518">
                    <inertial pos="0.064956 -0.004454 -0.010062" quat="0.388129 0.388821 0.636132 0.541765" mass="0.6" diaginertia="0.000443035 0.000421612 0.000259353"/>
                    <joint name="right_elbow_joint" pos="0 0 0" axis="0 1 0" range="-1.0472 2.0944" actuatorfrcrange="-25 25"/>
                    <geom type="mesh" contype="0" conaffinity="0" group="1" density="0" rgba="0.7 0.7 0.7 1" mesh="right_elbow_link"/>
                    <geom type="mesh" rgba="0.7 0.7 0.7 1" mesh="right_elbow_link" name="right_elbow_stl"/>
                    <body name="right_wrist_roll_link" pos="0.1 -0.00188791 -0.01">
                      <inertial pos="0.0171394 -0.000537591 4.8864e-07" quat="0.411667 0.575338 -0.411094 0.574906" mass="0.085445" diaginertia="5.48211e-05 4.96646e-05 3.57798e-05"/>
                      <joint name="right_wrist_roll_joint" pos="0 0 0" axis="1 0 0" range="-1.97222 1.97222" actuatorfrcrange="-25 25"/>
                      <geom type="mesh" contype="0" conaffinity="0" group="1" density="0" rgba="0.7 0.7 0.7 1" mesh="right_wrist_roll_link"/>
                      <geom type="mesh" rgba="0.7 0.7 0.7 1" mesh="right_wrist_roll_link" name="right_wrist_roll_stl"/>
                      <body name="right_wrist_pitch_link" pos="0.038 0 0">
                        <inertial pos="0.0229999 0.00111685 -0.00111658" quat="0.643608 0.293036 0.661363 0.249998" mass="0.48405" diaginertia="0.000430353 0.000429873 0.000164648"/>
                        <joint name="right_wrist_pitch_joint" pos="0 0 0" axis="0 1 0" range="-1.61443 1.61443" actuatorfrcrange="-25 25"/>
                        <geom type="mesh" contype="0" conaffinity="0" group="1" density="0" rgba="0.7 0.7 0.7 1" mesh="right_wrist_pitch_link"/>
                        <geom type="mesh" rgba="0.7 0.7 0.7 1" mesh="right_wrist_pitch_link" name="right_wrist_pitch_stl"/>
                        <body name="right_wrist_yaw_link" pos="0.046 0 0">
                          <inertial pos="0.0609957 -0.00246187 -5.70275e-05" quat="0.500265 0.514832 0.502953 0.481374" mass="0.393726" diaginertia="0.000531179 0.0004935 0.000248299"/>
                          <joint name="right_wrist_yaw_joint" pos="0 0 0" axis="0 0 1" range="-1.61443 1.61443" actuatorfrcrange="-25 25"/>
                          <geom type="mesh" contype="0" conaffinity="0" group="1" density="0" rgba="0.7 0.7 0.7 1" mesh="right_wrist_yaw_link"/>
                          <geom type="mesh" rgba="0.7 0.7 0.7 1" mesh="right_wrist_yaw_link" name="right_wrist_yaw_stl"/>
                          <!-- right 2f85_v4 -->
                          <body name="right_arm_base" childclass="2f85" pos="0.0415 -0.003 0" quat="0.5 0.5 0.5 0.5">
                            <inertial mass="0.777441" pos="0 -2.70394e-05 0.0354675" quat="1 0 0 0"
                              diaginertia="0.000260285 0.000225381 0.000152708"/>
                            <geom class="visual" pos="0 0 0.0108" quat="0 0 0 1"   mesh="base"/>
                            <geom class="visual" pos="0 0 0.004" quat="1 -1 0 0"   mesh="base_coupling"/>
                            <geom class="visual" pos="0 0 0.0108" quat="1 0 0 0"  material="metal" mesh="c-a01-85-open"/>
                            <geom name="right_arm_hand_capsule" class="collision" type="capsule" conaffinity="1" size="0.04 0.06" rgba="1 1 1 0.3" pos="0 0 0.01"/>
                            <geom name="right_arm_hand_right_side_capsule" class="visual" type="capsule"  
                              size="0.02 0.02" rgba="1 0 0 0.0" pos="-0.059 0.0 0.085" quat="0  -0.0784591 0 0.9969173"/>
                              <geom name="right_arm_hand_left_side_capsule" class="visual" type="capsule"  
                              size="0.02 0.02" rgba="1 0 0 0.0" pos="0.059 0.0 0.085" quat="0  0.0784591 0 0.9969173"/>
                              <!-- pos 1 y  2 z 3 x-->
                            <!-- right finger site -->
                            <site name="Right_gripper_center" pos="0 0 0.16" size="0.01" type="sphere" rgba="1 0 0 1"/>
                            <!-- Left-hand side 4-bar linkage -->
                            <body name="right_arm_left_driver" pos="-0.0306011 0.00475 0.0657045" quat="1 -1 0 0">
                              <inertial mass="0.00899563" pos="0 0.0177547 0.00107314" quat="0.681301 0.732003 0 0"
                                  diaginertia="1.72352e-06 1.60906e-06 3.22006e-07"/>
                              <joint name="right_arm_left_driver_joint" class="driver"/>
                              <geom class="visual" pos="0.0306011 0.0549045 -0.0047" quat="1 1 0 0"  material="metal" mesh="driver"/>
                              <body name="right_arm_left_coupler" pos="-0.0314249 0.00453223 -0.0102" quat="0 0 0 1">
                                <inertial mass="0.0140974" pos="0 0.00301209 0.0232175" quat="0.705636 -0.0455904 0.0455904 0.705636"
                                diaginertia="4.16206e-06 3.52216e-06 8.88131e-07"/>
                                <geom class="visual" pos="-0.062026 -0.0503723 0.0055" quat="1 -1 0 0"   mesh="coupler"/>
                                <geom name="right_arm_left_coupler_col_1" class="pad_box2" pos="0.005 0.025 0.01" quat="1 1 -0.1 0" type="capsule" size="0.009 0.02"/>
                                <geom name="right_arm_left_coupler_col_2" class="pad_box2" pos="0.005 0.025 0.001" quat="1 1 -0.1 0" type="capsule" size="0.009 0.02"/>
                              </body>
                            </body>
                            <body name="right_arm_left_spring_link" pos="-0.0127 -0.012 0.07222" quat="1 -1 0 0">
                              <inertial mass="0.0221642" pos="-8.65005e-09 0.0181624 0.0212658" quat="0.663403 -0.244737 0.244737 0.663403"
                                  diaginertia="8.96853e-06 6.71733e-06 2.63931e-06"/>
                              <joint name="right_arm_left_spring_link_joint" class="spring_link"/>
                              <geom class="visual" pos="0.0127 0.06142 0.01205" quat="1 1 0 0" type="mesh"  mesh="spring_link"/>
                              <body name="right_arm_left_follower" pos="-0.0382079 -0.0425003 0.00295" quat="0 -1 0 0">
                                <inertial mass="0.0125222" pos="0 -0.011046 0.0124786" quat="1 0.1664 0 0"
                                diaginertia="2.67415e-06 2.4559e-06 6.02031e-07"/>
                                <joint name="right_arm_left_follower" class="follower"/>
                                <geom class="visual" pos="0.0509079 -0.10392 -0.0091" quat="1 -1 0 0" type="mesh"  mesh="follower"/>
                                <geom class="visual" pos="0.0509079 -0.10392 -0.0091" quat="1 -1 0 0" type="mesh" material="metal" mesh="tongue"/>
                                <geom name="right_arm_left_follower_pad2" class="pad_box2" type="capsule" size="0.009 0.012 0.008" pos="-0.0035 -0.002 -0.009" quat="1 1 0 0"/>
                                <site name="right_arm_left_follower_site"  type="box" size="0.03 0.045 0.015" pos="0 -0.03 -0.01" 
                                        rgba="1 0 0 0.0"/>
                                <body name="right_arm_left_pad" pos="-0.0377897 -0.103916 -0.0091" quat="1 -1 0 0">
                                  <geom class="pad_box2" name="right_arm_left_finger_pad"/>
                                  <site name="right_arm_left_pad_site"  type="box" size="0.006 0.015 0.02" pos="0.042 0 0.13" 
                                      rgba="1 0 0 0.0"/>
                                </body>
                              </body>
                            </body>
                            <!-- Right-hand side 4-bar linkage -->
                            <body name="right_arm_right_driver" pos="0.0306011 -0.00475 0.0657045" quat="0 0 -1 1">
                              <inertial mass="0.00899563" pos="2.96931e-12 0.0177547 0.00107314" quat="0.681301 0.732003 0 0"
                              diaginertia="1.72352e-06 1.60906e-06 3.22006e-07"/>
                              <joint name="right_arm_right_driver_joint" class="driver"/>
                              <geom class="visual" pos="0.0306011 0.0549045 -0.0047" quat="1 1 0 0" material="metal" mesh="driver"/>
                              <body name="right_arm_right_coupler" pos="-0.0314249 0.00453223 -0.0102" quat="0 0 0 1">
                                <inertial mass="0.0140974" pos="0 0.00301209 0.0232175" quat="0.705636 -0.0455904 0.0455904 0.705636"
                                diaginertia="4.16206e-06 3.52216e-06 8.88131e-07"/>
                                <geom class="visual" pos="-0.062026 -0.0503723 0.0055" quat="1 -1 0 0"   mesh="coupler"/>
                                <geom name="right_arm_right_coupler_col_1" class="pad_box2" pos="0.005 0.025 0.01" quat="1 1 -0.1 0" type="capsule" size="0.009 0.02"/>
                                <geom name="right_arm_right_coupler_col_2" class="pad_box2" pos="0.005 0.025 0.001" quat="1 1 -0.1 0" type="capsule" size="0.009 0.02"/>
                              </body>
                            </body>
                            <body name="right_arm_right_spring_link" pos="0.0127 0.012 0.07222" quat="0 0 -1 1">
                              <inertial mass="0.0221642" pos="-8.65005e-09 0.0181624 0.0212658" quat="0.663403 -0.244737 0.244737 0.663403"
                              diaginertia="8.96853e-06 6.71733e-06 2.63931e-06"/>
                              <joint name="right_arm_right_spring_link_joint" class="spring_link"/>
                              <geom class="visual" pos="0.0127 0.06142 0.01205" quat="1 1 0 0"   mesh="spring_link"/>
                              <body name="right_arm_right_follower" pos="-0.0382079 -0.0425003 0.00295" quat="0 -1 0 0">
                                <inertial mass="0.0125222" pos="0 -0.011046 0.0124786" quat="1 0.1664 0 0"
                                diaginertia="2.67415e-06 2.4559e-06 6.02031e-07"/>
                                <joint name="right_arm_right_follower_joint" class="follower"/>
                                <geom class="visual" pos="0.0509079 -0.10392 -0.0091" quat="1 -1 0 0" material="metal" mesh="tongue"/>
                                <geom class="visual" pos="0.0509079 -0.10392 -0.0091" quat="1 -1 0 0" mesh="follower"/>
                                <geom name="right_arm_right_follower_pad2" class="pad_box2" type="capsule" size="0.009 0.012 0.008" pos="-0.0035 -0.002 -0.009" quat="1 1 0 0"/>
                                <site name="right_arm_right_follower_site"  type="box" size="0.03 0.045 0.015" pos="0 -0.03 -0.01" 
                                        rgba="1 0 0 0.0"/>
                                <body name="right_arm_right_pad" pos="-0.0377897 -0.103916 -0.0091" quat="1 -1 0 0">
                                  <geom class="pad_box2" name="right_arm_right_finger_pad"/>
                                <site name="right_arm_right_pad_site"  type="box" size="0.006 0.015 0.02" pos="0.042 0 0.13" 
                                      rgba="1 0 0 0.0"/>
                                </body>
                              </body>
                            </body>
                          </body>
                          
                          <!-- end right 2f85_v4 -->
                        </body>
                      </body>
                    </body>
                  </body>
                </body>
              </body>
            </body>
          </body>
        </body>
      </body>
    </body>
  </worldbody>


  <contact>
    <!-- left arm -->
    <exclude body1="left_arm_base" body2="left_arm_left_driver"/>
    <exclude body1="left_arm_base" body2="left_arm_right_driver"/>
    <exclude body1="left_arm_base" body2="left_arm_left_spring_link"/>
    <exclude body1="left_arm_base" body2="left_arm_right_spring_link"/>
    <exclude body1="left_arm_right_coupler" body2="left_arm_right_follower"/>
    <exclude body1="left_arm_left_coupler" body2="left_arm_left_follower"/>
    <exclude body1="left_arm_base" body2="left_wrist_roll_link"/>
    
    <!-- right arm -->
    <exclude body1="right_arm_base" body2="right_arm_left_driver"/>
    <exclude body1="right_arm_base" body2="right_arm_right_driver"/>
    <exclude body1="right_arm_base" body2="right_arm_left_spring_link"/>
    <exclude body1="right_arm_base" body2="right_arm_right_spring_link"/>
    <exclude body1="right_arm_right_coupler" body2="right_arm_right_follower"/>
    <exclude body1="right_arm_left_coupler" body2="right_arm_left_follower"/>
    <exclude body1="right_arm_base" body2="right_wrist_roll_link"/>
  </contact>


  <!--
    This adds stability to the model by having a tendon that distributes the forces between both
    joints, such that the equality constraint doesn't have to do that much work in order to equalize
    both joints. Since both joints share the same sign, we split the force between both equally by
    setting coef=0.485
  -->
  <tendon>
    <fixed name="left_split">
      <joint joint="left_arm_right_driver_joint" coef="0.485"/>
      <joint joint="left_arm_left_driver_joint" coef="0.485"/>
    </fixed>
    <fixed name="right_split">
      <joint joint="right_arm_right_driver_joint" coef="0.485"/>
      <joint joint="right_arm_left_driver_joint" coef="0.485"/>
    </fixed>
  </tendon>

  <equality>
   
    <connect anchor="-0.0179014 -0.00651468 0.0044" body1="left_arm_right_follower" body2="left_arm_right_coupler" solimp="0.95 0.99 0.001" solref="0.005 1"/>
    <connect anchor="-0.0179014 -0.00651468 0.0044" body1="left_arm_left_follower" body2="left_arm_left_coupler" solimp="0.95 0.99 0.001" solref="0.005 1"/>
    <joint joint1="left_arm_right_driver_joint" joint2="left_arm_left_driver_joint" polycoef="0 1 0 0 0" solimp="0.95 0.99 0.001" solref="0.005 1"/>

    <connect anchor="-0.0179014 -0.00651468 0.0044" body1="right_arm_right_follower" body2="right_arm_right_coupler" solimp="0.95 0.99 0.001" solref="0.005 1"/>
    <connect anchor="-0.0179014 -0.00651468 0.0044" body1="right_arm_left_follower" body2="right_arm_left_coupler" solimp="0.95 0.99 0.001" solref="0.005 1"/>
    <joint joint1="right_arm_right_driver_joint" joint2="right_arm_left_driver_joint" polycoef="0 1 0 0 0" solimp="0.95 0.99 0.001" solref="0.005 1"/>
  </equality>

 <actuator>
    <motor name="left_hip_pitch_joint" joint="left_hip_pitch_joint" gear="1" ctrllimited="true" ctrlrange="-200 200"/>
    <motor name="left_hip_roll_joint" joint="left_hip_roll_joint" gear="1" ctrllimited="true" ctrlrange="-200 200"/>
    <motor name="left_hip_yaw_joint" joint="left_hip_yaw_joint" gear="1" ctrllimited="true" ctrlrange="-200 200"/>
    <motor name="left_knee_joint" joint="left_knee_joint" gear="1" ctrllimited="true" ctrlrange="-200 200"/>
    <motor name="left_ankle_pitch_joint" joint="left_ankle_pitch_joint" gear="1" ctrllimited="true" ctrlrange="-200 200"/>
    <motor name="left_ankle_roll_joint" joint="left_ankle_roll_joint" gear="1" ctrllimited="true" ctrlrange="-200 200"/>
    <motor name="right_hip_pitch_joint" joint="right_hip_pitch_joint" gear="1" ctrllimited="true" ctrlrange="-200 200"/>
    <motor name="right_hip_roll_joint" joint="right_hip_roll_joint" gear="1" ctrllimited="true" ctrlrange="-200 200"/>
    <motor name="right_hip_yaw_joint" joint="right_hip_yaw_joint" gear="1" ctrllimited="true" ctrlrange="-200 200"/>
    <motor name="right_knee_joint" joint="right_knee_joint" gear="1" ctrllimited="true" ctrlrange="-200 200"/>
    <motor name="right_ankle_pitch_joint" joint="right_ankle_pitch_joint" gear="1" ctrllimited="true" ctrlrange="-200 200"/>
    <motor name="right_ankle_roll_joint" joint="right_ankle_roll_joint" gear="1" ctrllimited="true" ctrlrange="-200 200"/>
    <motor name="waist_yaw_joint" joint="waist_yaw_joint" gear="1" ctrllimited="true" ctrlrange="-200 200"/>
    <!-- <motor name="waist_roll_joint" joint="waist_roll_joint" gear="1" ctrllimited="true" ctrlrange="-200 200"/>
    <motor name="waist_pitch_joint" joint="waist_pitch_joint" gear="1" ctrllimited="true" ctrlrange="-200 200"/> -->
    <motor name="left_shoulder_pitch_joint" joint="left_shoulder_pitch_joint" gear="1" ctrllimited="true" ctrlrange="-200 200"/>
    <motor name="left_shoulder_roll_joint" joint="left_shoulder_roll_joint" gear="1" ctrllimited="true" ctrlrange="-200 200"/>
    <motor name="left_shoulder_yaw_joint" joint="left_shoulder_yaw_joint" gear="1" ctrllimited="true" ctrlrange="-200 200"/>
    
    <motor name="left_elbow_joint" joint="left_elbow_joint" gear="1" ctrllimited="true" ctrlrange="-200 200"/>
    <motor name="left_wrist_roll_joint" joint="left_wrist_roll_joint"/>
    <motor name="left_wrist_pitch_joint" joint="left_wrist_pitch_joint"/>
    <motor name="left_wrist_yaw_joint" joint="left_wrist_yaw_joint"/>
    
    <motor name="right_shoulder_pitch_joint" joint="right_shoulder_pitch_joint" gear="1" ctrllimited="true" ctrlrange="-200 200"/>
    <motor name="right_shoulder_roll_joint" joint="right_shoulder_roll_joint" gear="1" ctrllimited="true" ctrlrange="-200 200"/>
    <motor name="right_shoulder_yaw_joint" joint="right_shoulder_yaw_joint" gear="1" ctrllimited="true" ctrlrange="-200 200"/>
    <motor name="right_elbow_joint" joint="right_elbow_joint" gear="1" ctrllimited="true" ctrlrange="-200 200"/>

    <motor name="right_wrist_roll_joint" joint="right_wrist_roll_joint"/>
    <motor name="right_wrist_pitch_joint" joint="right_wrist_pitch_joint"/>
    <motor name="right_wrist_yaw_joint" joint="right_wrist_yaw_joint"/>
    <!-- left arm -->

    <general class="2f85" name="left_arm_fingers_actuator" tendon="left_split" forcerange="-5 5" ctrlrange="0 255"
      gainprm="0.3137255 0 0" biasprm="0 -100 -10"/>
    <!-- right arm -->

    <general class="2f85" name="right_arm_fingers_actuator" tendon="right_split" forcerange="-5 5" ctrlrange="0 255"
      gainprm="0.3137255 0 0" biasprm="0 -100 -10"/>
  </actuator>

  <sensor>
    <gyro name="imu-torso-angular-velocity" site="imu_in_torso" noise="5e-4" cutoff="34.9"/>
    <accelerometer name="imu-torso-linear-acceleration" site="imu_in_torso" noise="1e-2" cutoff="157"/>
    <gyro name="imu-pelvis-angular-velocity" site="imu_in_pelvis" noise="5e-4" cutoff="34.9"/>
    <accelerometer name="imu-pelvis-linear-acceleration" site="imu_in_pelvis" noise="1e-2" cutoff="157"/>
     <touch name="left_arm_left_follower_touch"  site="left_arm_left_follower_site"/>
    <touch name="left_arm_right_follower_touch"  site="left_arm_right_follower_site"/>
    <touch name="right_arm_left_follower_touch"  site="right_arm_left_follower_site"/>
    <touch name="right_arm_right_follower_touch" site="right_arm_right_follower_site"/>
  
    <touch name="left_arm_left_pad_touch"  site="left_arm_left_pad_site"/>
    <touch name="left_arm_right_pad_touch" site="left_arm_right_pad_site"/>
    <touch name="right_arm_left_pad_touch"  site="right_arm_left_pad_site"/>
    <touch name="right_arm_right_pad_touch" site="right_arm_right_pad_site"/>

  </sensor>
  
  <!-- setup scene -->
  <statistic center="1.0 0.7 1.0" extent="0.8"/>
  <visual>
    <headlight diffuse="0.6 0.6 0.6" ambient="0.1 0.1 0.1" specular="0.9 0.9 0.9"/>
    <rgba haze="0.15 0.25 0.35 1"/>
    <global azimuth="-140" elevation="-20"/>
  </visual>
  <asset>
    <texture type="skybox" builtin="flat" rgb1="0 0 0" rgb2="0 0 0" width="512" height="3072"/>
    <texture type="2d" name="groundplane" builtin="checker" mark="edge" rgb1="0.2 0.3 0.4" rgb2="0.1 0.2 0.3" markrgb="0.8 0.8 0.8" width="300" height="300"/>
    <material name="groundplane" texture="groundplane" texuniform="true" texrepeat="5 5" reflectance="0.2"/>
  </asset>
  <worldbody>
    <light pos="1 0 3.5" dir="0 0 -1" directional="true"/>
    <geom name="floor" size="0 0 0.05" type="plane" material="groundplane"/>

    <body name="Left_gripper_center_target" mocap="true" pos="0.25 0.15 0.85" quat="0.5 0.5 0.5 0.5">
       <geom type="box" size=".04 .04 .04" contype="0" conaffinity="0" rgba=".6 .3 .3 .2"/>
       <site type="sphere" size="0.01" rgba="0 0 1 1" group="1"/>
    </body>
    <body name="Right_gripper_center_target" mocap="true" pos="0.25 -0.15 0.85" quat="0.5 0.5 0.5 0.5">
       <geom type="box" size=".04 .04 .04" contype="0" conaffinity="0" rgba=".3 .6 .3 .2"/>
       <site type="sphere" size="0.01" rgba="1 0 0 1" group="1"/>
    </body>
    
  </worldbody>

  <keyframe>
    <key name='home' qpos='0 0 0.79  1 0 0 0
                            -0.2 0 0 0.4 -0.2 0
                            -0.2 0 0 0.4 -0.2 0   
                            0    
                            0 0 0 0 0 0 0  0 0 0 0 0 0    
                            0 0 0 0 0 0 0  0 0 0 0 0 0  
      '/>
  </keyframe>


</mujoco>
